<?xml version="1.0"?>
<!-- Chassis Width: 0.387m -->
<!-- Chassis Length: 0.642m -->
<!-- Chassis Height: 0.224m -->
<!-- Wheel Diameter: 0.315m -->
<!-- Wheel Width: 0.105m -->
<!-- Wheel to Body: 0.125m -->
<!-- Axle Distance: 0.386m -->
<!-- Calculation 1: 0.1185m (0.237 / 2) -->
<!-- Calculation 2: 0.193m (0.386 / 2) -->
<!-- Calculation 3: 0.2635m (0.387 / 2 + 0.07) -->

<!-- Front Lidar Width: 0.155m -->
<!-- Front Lidar Length: 0.155m -->
<!-- Front Lidar Height: 0.185m -->
<robot name="Junior">
    <material name="black">
        <color rgba="0 0 0 1"/>
    </material>
    
    <material name="red">
        <color rgba="1 0 0 1"/>
    </material>

    <material name="skyblue">
        <color rgba="0.0 0.75 1.0 1.0"/>
    </material>

    <!-- Base Link -->
    <link name="base_link"/>

    <!-- Chassis Link -->
    <link name="Chassis">
        <visual>
            <geometry>
                <mesh filename="file://$(find junior_model)/meshes/robitChassis.stl"/>
            </geometry>
            <material name="red"/>
        </visual>
        <collision>
            <geometry>
                <mesh filename="file://$(find junior_model)/meshes/robitChassis.stl"/>
            </geometry>
        </collision>
       <inertial>
            <mass value="0.01"/>
            <inertia ixx="0.0" ixy="0.0" ixz="0.0" iyy="0.0" iyz="0.0" izz="0.0"/>
        </inertial>
    </link>

    <!-- Front Bumper Link -->
    <link name="FrontBumper">
        <visual>
            <geometry>
                <mesh filename="file://$(find junior_model)/meshes/robitFrontBumper.stl"/>
            </geometry>
            <material name="black"/>
        </visual>
        <collision>
            <geometry>
                <mesh filename="file://$(find junior_model)/meshes/robitFrontBumper.stl"/>
            </geometry>
        </collision>
        <inertial>
            <mass value="0.01"/>
            <inertia ixx="0.0" ixy="0.0" ixz="0.0" iyy="0.0" iyz="0.0" izz="0.0"/>
        </inertial>
    </link>


    <!-- Back Bumper Link -->
    <link name="BackBumper">
        <visual>
            <geometry>
                <mesh filename="file://$(find junior_model)/meshes/robitBackBumper.stl"/>
            </geometry>
            <material name="black"/>
        </visual>
        <collision>
            <geometry>
                <mesh filename="file://$(find junior_model)/meshes/robitBackBumper.stl"/>
            </geometry>
        </collision>
        <inertial>
            <mass value="0.01"/>
            <inertia ixx="0.0" ixy="0.0" ixz="0.0" iyy="0.0" iyz="0.0" izz="0.0"/>
        </inertial>
    </link>


    <!-- Front Lidar Link -->
    <link name="FrontLidar">
        <visual>
            <geometry>
                <mesh filename="file://$(find junior_model)/meshes/robitFrontLidarCase.stl"/>
            </geometry>
            <material name="skyblue"/>
        </visual>
        <collision>
            <geometry>
                <mesh filename="file://$(find junior_model)/meshes/robitFrontLidarCase.stl"/>
            </geometry>
        </collision>
        <inertial>
            <mass value="0.01"/>
            <inertia ixx="0.0" ixy="0.0" ixz="0.0" iyy="0.0" iyz="0.0" izz="0.0"/>
        </inertial>
    </link>

    <!-- Front Lidar Glass Link -->
    <link name="FrontLidarGlass">
        <visual>
            <geometry>
                <mesh filename="file://$(find junior_model)/meshes/robitFrontLidarGlass.stl"/>
            </geometry>
            <material name="black"/>
        </visual>
        <collision>
            <geometry>
                <mesh filename="file://$(find junior_model)/meshes/robitFrontLidarGlass.stl"/>
            </geometry>
        </collision>
        <inertial>
            <mass value="0.01"/>
            <inertia ixx="0.0" ixy="0.0" ixz="0.0" iyy="0.0" iyz="0.0" izz="0.0"/>
        </inertial>
    </link>

    <!-- Left Front Link -->
    <link name="WheelLeftFront">
        <visual>
            <geometry>
                <mesh filename="file://$(find junior_model)/meshes/robitWheel.stl"/>
            </geometry>
            <material name="black"/>
        </visual>
        <collision>
            <geometry>
                <mesh filename="file://$(find junior_model)/meshes/robitWheel.stl"/>
            </geometry>
        </collision>
        <inertial>
            <mass value="0.01"/>
            <inertia ixx="0.0" ixy="0.0" ixz="0.0" iyy="0.0" iyz="0.0" izz="0.0"/>
        </inertial>
    </link>

    <!-- Right Front Link -->
    <link name="WheelRightFront">
        <visual>
            <geometry>
                <mesh filename="file://$(find junior_model)/meshes/robitWheel.stl"/>
            </geometry>
            <material name="black"/>
        </visual>
        <collision>
            <geometry>
                <mesh filename="file://$(find junior_model)/meshes/robitWheel.stl"/>
            </geometry>
        </collision>
       <inertial>
            <mass value="0.01"/>
            <inertia ixx="0.0" ixy="0.0" ixz="0.0" iyy="0.0" iyz="0.0" izz="0.0"/>
        </inertial>
    </link>

    <!-- Left Back Link -->
    <link name="WheelLeftBack">
        <visual>
            <geometry>
                <mesh filename="file://$(find junior_model)/meshes/robitWheel.stl"/>
            </geometry>
            <material name="black"/>
        </visual>
        <collision>
            <geometry>
                <mesh filename="file://$(find junior_model)/meshes/robitWheel.stl"/>
            </geometry>
        </collision>
        <inertial>
            <mass value="0.01"/>
            <inertia ixx="0.0" ixy="0.0" ixz="0.0" iyy="0.0" iyz="0.0" izz="0.0"/>
        </inertial>
    </link>

    <!-- Right Back Link -->
    <link name="WheelRightBack">
        <visual>
            <geometry>
                <mesh filename="file://$(find junior_model)/meshes/robitWheel.stl"/>
            </geometry>
            <material name="black"/>
        </visual>
        <collision>
            <geometry>
                <mesh filename="file://$(find junior_model)/meshes/robitWheel.stl"/>
            </geometry>
        </collision>
        <inertial>
            <mass value="0.01"/>
            <inertia ixx="0.0" ixy="0.0" ixz="0.0" iyy="0.0" iyz="0.0" izz="0.0"/>
        </inertial>
    </link>

    <gazebo reference="Chassis">
        <visual>
            <material>
                <ambient>0 0 0 0</ambient>
                <diffuse>1 1 0 1</diffuse>
                <specular>1 1 0 1</specular>
                <emissive>0 0 0 0</emissive>
            </material>
        </visual>
    </gazebo>
    <gazebo reference="FrontBumper">
        <material>Gazebo/Black</material>
    </gazebo>
    <gazebo reference="BackBumper">
        <material>Gazebo/Black</material>
    </gazebo>
    <gazebo reference="FrontLidar">
        <material>Gazebo/Turquoise</material>
    </gazebo>
    <gazebo reference="FrontLidarGlass">
        <material>Gazebo/Bricks</material>
    </gazebo>
    <gazebo reference="WheelLeftFront">
        <material>Gazebo/Black</material>
    </gazebo>
    <gazebo reference="WheelRightFront">
        <material>Gazebo/Black</material>
    </gazebo>
    <gazebo reference="WheelLeftBack">
        <material>Gazebo/Black</material>
    </gazebo>
    <gazebo reference="WheelRightBack">
        <material>Gazebo/Black</material>
    </gazebo>



    <!-- START OF JOINTS -->
    <joint name="ChassisJoint" type="fixed">
        <parent link="base_link"/>
        <child link="Chassis"/>
        <origin xyz="1 0 0.23"/>
    </joint>

    <joint name="FrontLidarHolster" type="fixed">
        <parent link="Chassis"/>
        <child link="FrontLidar"/>
        <origin xyz="0.321 0 -0.0197"/> 
    </joint>

    <joint name="FrontLidarVision" type="fixed">
        <parent link="FrontLidar"/>
        <child link="FrontLidarGlass"/>
        <origin xyz="0.075 0 0"/> 
    </joint>

    <joint name="AxleLeftFront" type="continuous">
        <parent link="Chassis"/>
        <child link="WheelLeftFront"/>
        <origin xyz="0.193 0.2635 -0.07" rpy="0 0 0"/>
        <axis xyz="0 1 0"/>
    </joint>
    
    <joint name="AxleRightFront" type="continuous">
        <parent link="Chassis"/>
        <child link="WheelRightFront"/>
        <origin xyz="0.193 -0.2635 -0.07" rpy="0 0 0"/>
        <axis xyz="0 1 0"/>
    </joint>

    <joint name="AxleLeftBack" type="continuous">
        <parent link="Chassis"/>
        <child link="WheelLeftBack"/>
        <origin xyz="-0.193 0.2635 -0.07" rpy="0 0 0"/>
        <axis xyz="0 1 0"/>
    </joint>

    <joint name="AxleRightBack" type="continuous">
        <parent link="Chassis"/>
        <child link="WheelRightBack"/>
        <origin xyz="-0.193 -0.2635 -0.07" rpy="0 0 0"/>
        <axis xyz="0 1 0"/>
    </joint>

    <joint name="FrontBumperLoc" type="fixed">
        <parent link="Chassis"/>
        <child link="FrontBumper"/>
        <origin xyz="0.321 0 0.025" rpy="0 0 0"/>
    </joint>

    <joint name="BackBumperLoc" type="fixed">
        <parent link="Chassis"/>
        <child link="BackBumper"/>
        <origin xyz="-0.321 0 -0.0795" rpy="0 0 0"/>
    </joint>
</robot>